Workbook

Sheet Attachement
C1: Libreville, le 28 janvier 2026
A2: ATTACHEMENT N°1
A3: ESSAI
A5: Période du 25 Juillet 2025 au 31 Decembre 2025
B6: MONTANT DU MARCHE TTC :
B7: Delai Contractuel :
B8: N° | C8: Désignation | D8: Unités | E8: Quantités | F8: PROGRESSION
F9: Prestations précédentes | G9: Prestations du Mois | H9: Prestations cumulées | I9: % avment | J9: Prestations restantes
F10: Qté | G10: Qté | H10: Qté | J10: Qté Restante
B11: I. VOIE SUR LA BERGE DE LA LOWE
B12: 000 | C12: INSTALLATION DE CHANTIER
B13: N° | C13: Désignation | D13: Unités | E13: Quantités
B14: 001 | C14: Installation générale de chantier et des services | D14: Ft | E14: 1 | H14: =+G14+F14 -> 0 | I14: =+H14/E14 -> 0 | J14: =+E14-H14 -> 1
B15: 002 | C15: Levé topografique, études de projet APD et élaboration des plans d'exécution | D15: Ft | E15: 1 | H15: =+G15+F15 -> 0 | I15: =+H15/E15 -> 0 | J15: =+E15-H15 -> 1
B16: 003 | C16: Plan d'assurance qualité des travaux | D16: Ft | E16: 1 | H16: =+G16+F16 -> 0 | I16: =+H16/E16 -> 0 | J16: =+E16-H16 -> 1
B17: 004 | C17: Compagne géotechnique pendant les travaux de chaussées | D17: Ft | E17: 1 | G17: 0.75 | H17: =+G17+F17 -> 0.75 | I17: =+H17/E17 -> 0.75 | J17: =+E17-H17 -> 0.25
B18: 005 | C18: Etude Bathymetrique | D18: Ft | E18: 1 | G18: 0.9 | H18: =+G18+F18 -> 0.9 | I18: =+H18/E18 -> 0.9 | J18: =+E18-H18 -> 0.1
B19: 006 | C19: Provision pour déplacement de réseaux | D19: Ft | E19: 1 | H19: =+G19+F19 -> 0 | I19: =+H19/E19 -> 0 | J19: =+E19-H19 -> 1
B20: 007 | C20: Provision pour déguerpissement et/ou expropriation | D20: Ft | E20: 1 | H20: =+G20+F20 -> 0 | I20: =+H20/E20 -> 0 | J20: =+E20-H20 -> 1
B22: 100 | C22: TRAVAUX PREPARATOIRES DEGAGEMENT DES EMPRISES
B23: N° | C23: Désignation | D23: Unités | E23: Quantités
B24: 101 | C24: Débroussaillement avec essouchement / Nettoyage de terrain | D24: m² | E24: 3000 | G24: 42311.2 | H24: =+G24+F24 -> 42311.2 | I24: =+H24/E24 -> 14.103733 | J24: =+E24-H24 -> -39311.2
B25: 102 | C25: Abattage et dessouchage des arbres de circonférence supérieure ou égale à 1 m | D25: u | E25: 200 | H25: =+G25+F25 -> 0 | I25: =+H25/E25 -> 0 | J25: =+E25-H25 -> 200
B26: 103 | C26: Décapage de terre végétale sur 0,2 m d'épaisseur | D26: m² | E26: 400 | G26: 564.15 | H26: =+G26+F26 -> 564.15 | I26: =+H26/E26 -> 1.410375 | J26: =+E26-H26 -> -164.15
B28: 200 | C28: TERRASSEMENTS GENERAUX
B29: N° | C29: Désignation | D29: Unités | E29: Quantités
B30: 201 | C30: Déblais mis en dépôt | D30: m³ | E30: 1500 | G30: 2541.4 | H30: =+G30+F30 -> 2541.4 | I30: =+H30/E30 -> 1.6942667 | J30: =+E30-H30 -> -1041.4
B31: 202 | C31: Purge de terre de mauvaise tenue et substitution au-delà de 50 cm | D31: m³ | E31: 5050 | G31: 5850 | H31: =+G31+F31 -> 5850 | I31: 0 | J31: -
B32: 203 | C32: Remblais provenant d'emprunts en matériaux naturels | D32: m³ | E32: 53000 | G32: 5314 | H32: =+G32+F32 -> 5314 | I32: =+H32/E32 -> 0.10026415 | J32: =+E32-H32 -> 47686
B33: 204 | C33: Réglage et compactage de l'arase de la plateforme des terrassements | D33: m² | E33: 45000 | H33: =+G33+F33 -> 0 | I33: 0 | J33: =+E33-H33 -> 45000
B34: 205 | C34: Enrochement berge apres purge | D34: m3 | E34: 31000 | G34: 6675 | H34: =+G34+F34 -> 6675 | I34: =+H34/E34 -> 0.21532258 | J34: =+E34-H34 -> 24325
B35: 206 | C35: Mise en place d'une berge en matériaux traités aux liants hydrauliques | D35: m² | E35: 10200 | H35: =+G35+F35 -> 0 | I35: =+H35/E35 -> 0 | J35: =+E35-H35 -> 10200
B37: 300 | C37: CHAUSSEE
B38: N° | C38: Désignation | D38: Unités | E38: Quantités
B39: 301 | C39: Fourniture, transport et mise en œuvre de graveleux lateritique pour couche de fondation - épaisseur = 35 cm | D39: m³ | E39: 17000 | H39: =+G39+F39 -> 0 | I39: =+H39/E39 -> 0 | J39: =+E39-H39 -> 17000
B40: 302 | C40: Fourniture, transport et mise en œuvre de grave concassé 0/25 pour la couche de base - épaisseur = 25 cm | D40: m³ | E40: 5200 | H40: =+G40+F40 -> 0 | I40: =+H40/E40 -> 0 | J40: =+E40-H40 -> 5200
B41: 303 | C41: Fourniture et mise œuvre de beton dosé à 200 Kg/m3 pour revetement de trottoir - épaisseur = 10 cm | D41: m³ | E41: 1020 | H41: =+G41+F41 -> 0 | I41: =+H41/E41 -> 0 | J41: =+E41-H41 -> 1020
B42: 304 | C42: Revêtement en béton bitumineux ( 7 cm ) | D42: m³ | E42: 1300 | H42: =+G42+F42 -> 0 | I42: =+H42/E42 -> 0 | J42: =+E42-H42 -> 1300
B43: 305 | C43: Imprégnation MRC 400-600 | D43: m² | E43: 20000 | H43: =+G43+F43 -> 0 | I43: =+H43/E43 -> 0 | J43: =+E43-H43 -> 20000
B44: 307 | C44: Béton Bitumineux Minces pour piste cyclabe | D44: m³ | E44: 210 | H44: =+G44+F44 -> 0 | I44: =+H44/E44 -> 0 | J44: =+E44-H44 -> 210
...

Sheet Décompte
C1: =+Attachement!C1 -> Libreville, le 28 janvier 2026
A3: DECOMPTE PROVISOIRE N°1
A4: ESSAI
A6: =+Attachement!A5 -> Période du 25 Juillet 2025 au 31 Decembre 2025
B7: MONTANT DU MARCHE TTC :
B8: Delai Contractuel : ... MOIS
C10: Désignation | D10: Unités | E10: Quantités | F10: Prix unitaire | G10: Prix total | H10: PROGRESSION
H11: Prestations précédentes | J11: Prestations du Mois | L11: Prestations cumulées (en FCFA) | N11: % avment | O11: Prestations restantes (en FCFA)
H12: Qté | I12: Montant | J12: Qté | K12: Montant | L12: Qté | M12: Montant | O12: Qté Restante | P12: CA Restant
B13: I. VOIE SUR LA BERGE DE LA LOWE
B14: 000 | C14: INSTALLATION DE CHANTIER
B15: N° | C15: Désignation | D15: Unités | E15: Quantités
B16: 001 | C16: Installation générale de chantier et des services | D16: Ft | E16: =+Attachement!E14 -> 1 | F16: 100000000 | G16: =+E16*F16 -> 100000000 | H16: =+Attachement!F14 -> 0 | J16: =+Attachement!H14 -> 0 | K16: =+J16*F16 -> 0 | L16: =+J16+H16 -> 0 | M16: =+K16+I16 -> 0 | N16: =+M16/G16 -> 0 | O16: =+E16-L16 -> 1 | P16: =+G16-M16 -> 100000000
B17: 002 | C17: Levé topografique, études de projet APD et élaboration des plans d'exécution | D17: Ft | E17: =+Attachement!E15 -> 1 | F17: 15000000 | G17: =+E17*F17 -> 15000000 | H17: =+Attachement!F15 -> 0 | J17: =+Attachement!H15 -> 0 | K17: =+J17*F17 -> 0 | L17: =+J17+H17 -> 0 | M17: =+K17+I17 -> 0 | N17: =+M17/G17 -> 0 | O17: =+E17-L17 -> 1 | P17: =+G17-M17 -> 15000000
B18: 003 | C18: Plan d'assurance qualité des travaux | D18: Ft | E18: =+Attachement!E16 -> 1 | F18: 21000000 | G18: =+E18*F18 -> 21000000 | H18: =+Attachement!F16 -> 0 | J18: =+Attachement!H16 -> 0 | K18: =+J18*F18 -> 0 | L18: =+J18+H18 -> 0 | M18: =+K18+I18 -> 0 | N18: =+M18/G18 -> 0 | O18: =+E18-L18 -> 1 | P18: =+G18-M18 -> 21000000
B19: 004 | C19: Compagne géotechnique pendant les travaux de chaussées | D19: Ft | E19: =+Attachement!E17 -> 1 | F19: 18000000 | G19: =+E19*F19 -> 18000000 | H19: =+Attachement!F17 -> 0 | J19: =+Attachement!H17 -> 0.75 | K19: =+J19*F19 -> 13500000 | L19: =+J19+H19 -> 0.75 | M19: =+K19+I19 -> 13500000 | N19: =+M19/G19 -> 0.75 | O19: =+E19-L19 -> 0.25 | P19: =+G19-M19 -> 4500000
B20: 005 | C20: Etude Bathymetrique | D20: Ft | E20: =+Attachement!E18 -> 1 | F20: 13000000 | G20: =+E20*F20 -> 13000000 | H20: =+Attachement!F18 -> 0 | J20: =+Attachement!H18 -> 0.9 | K20: =+J20*F20 -> 11700000 | L20: =+J20+H20 -> 0.9 | M20: =+K20+I20 -> 11700000 | N20: =+M20/G20 -> 0.9 | O20: =+E20-L20 -> 0.1 | P20: =+G20-M20 -> 1300000
B21: 006 | C21: Provision pour déplacement de réseaux | D21: Ft | E21: =+Attachement!E19 -> 1 | F21: 23000000 | G21: =+E21*F21 -> 23000000 | H21: =+Attachement!F19 -> 0 | J21: =+Attachement!H19 -> 0 | K21: =+J21*F21 -> 0 | L21: =+J21+H21 -> 0 | M21: =+K21+I21 -> 0 | N21: =+M21/G21 -> 0 | O21: =+E21-L21 -> 1 | P21: =+G21-M21 -> 23000000
B22: 007 | C22: Provision pour déguerpissement et/ou expropriation | D22: Ft | E22: =+Attachement!E20 -> 1 | F22: 8000000 | G22: =+E22*F22 -> 8000000 | H22: =+Attachement!F20 -> 0 | J22: =+Attachement!H20 -> 0 | K22: =+J22*F22 -> 0 | L22: =+J22+H22 -> 0 | M22: =+K22+I22 -> 0 | N22: =+M22/G22 -> 0 | O22: =+E22-L22 -> 1 | P22: =+G22-M22 -> 8000000
C23: Total Poste 000 | G23: =+SUBTOTAL(9,G15:G22) -> 198000000 | I23: =+SUBTOTAL(9,I15:I22) -> 0 | K23: =+SUBTOTAL(9,K15:K22) -> 25200000 | M23: =+SUBTOTAL(9,M15:M22) -> 25200000 | N23: =+M23/G23 -> 0.12727273 | P23: =+SUBTOTAL(9,P15:P22) -> 172800000
B24: 100 | C24: TRAVAUX PREPARATOIRES DEGAGEMENT DES EMPRISES
B25: N° | C25: Désignation | D25: Unités | E25: Quantités
B26: 101 | C26: Débroussaillement avec essouchement / Nettoyage de terrain | D26: m² | E26: =+Attachement!E24 -> 3000 | F26: 720 | G26: =+E26*F26 -> 2160000 | H26: =+Attachement!F24 -> 0 | I26: =H26*F26 -> 0 | J26: =+Attachement!G24 -> 42311.2 | K26: =+J26*F26 -> 30464064 | L26: =+J26+H26 -> 42311.2 | M26: =+K26+I26 -> 30464064 | N26: =+M26/G26 -> 14.103733 | O26: =+E26-L26 -> -39311.2 | P26: =+G26-M26 -> -28304064
B27: 102 | C27: Abattage et dessouchage des arbres de circonférence supérieure ou égale à 1 m | D27: u | E27: =+Attachement!E25 -> 200 | F27: 56000 | G27: =+E27*F27 -> 11200000 | H27: =+Attachement!F25 -> 0 | I27: =H27*F27 -> 0 | J27: =+Attachement!G25 -> 0 | K27: =+J27*F27 -> 0 | L27: =+J27+H27 -> 0 | M27: =+K27+I27 -> 0 | N27: =+M27/G27 -> 0 | O27: =+E27-L27 -> 200 | P27: =+G27-M27 -> 11200000
B28: 103 | C28: Décapage de terre végétale sur 0,2 m d'épaisseur | D28: m² | E28: =+Attachement!E26 -> 400 | F28: 1720 | G28: =+E28*F28 -> 688000 | H28: =+Attachement!F26 -> 0 | I28: =H28*F28 -> 0 | J28: =+Attachement!G26 -> 564.15 | K28: =+J28*F28 -> 970338 | L28: =+J28+H28 -> 564.15 | M28: =+K28+I28 -> 970338 | O28: =+E28-L28 -> -164.15 | P28: =+G28-M28 -> -282338
C29: Total Poste 100 | G29: =+SUBTOTAL(9,G25:G28) -> 14048000 | I29: =+SUBTOTAL(9,I25:I28) -> 0 | K29: =+SUBTOTAL(9,K25:K28) -> 31434402 | M29: =+SUBTOTAL(9,M25:M28) -> 31434402 | N29: =+M29/G29 -> 2.2376425 | P29: =+SUBTOTAL(9,P25:P28) -> -17386402
B30: 200 | C30: TERRASSEMENTS GENERAUX
B31: N° | C31: Désignation | D31: Unités | E31: Quantités
B32: 201 | C32: Déblais mis en dépôt | D32: m³ | E32: =+Attachement!E30 -> 1500 | F32: 2350 | G32: =+E32*F32 -> 3525000 | H32: =+Attachement!F30 -> 0 | I32: =H32*F32 -> 0 | J32: =+Attachement!G30 -> 2541.4 | K32: =+J32*F32 -> 5972290 | L32: =+J32+H32 -> 2541.4 | M32: =+K32+I32 -> 5972290 | N32: =+M32/G32 -> 1.6942667 | O32: =+E32-L32 -> -1041.4 | P32: =+G32-M32 -> -2447290
B33: 202 | C33: Purge de terre de mauvaise tenue et substitution au-delà de 50 cm | D33: m³ | E33: =+Attachement!E31 -> 5050 | F33: 25000 | G33: =+E33*F33 -> 126250000 | H33: =+Attachement!F31 -> 0 | I33: =H33*F33 -> 0 | J33: =+Attachement!G31 -> 5850 | K33: =+J33*F33 -> 146250000 | L33: =+J33+H33 -> 5850 | M33: =+K33+I33 -> 146250000 | P33: =+G33-M33 -> -20000000
B34: 203 | C34: Remblais provenant d'emprunts en matériaux naturels | D34: m³ | E34: =+Attachement!E32 -> 53000 | F34: 25000 | G34: =+E34*F34 -> 1325000000 | H34: =+Attachement!F32 -> 0 | I34: =H34*F34 -> 0 | J34: =+Attachement!G32 -> 5314 | K34: =+J34*F34 -> 132850000 | L34: =+J34+H34 -> 5314 | M34: =+K34+I34 -> 132850000 | N34: =+M34/G34 -> 0.10026415 | O34: =+E34-L34 -> 47686 | P34: =+G34-M34 -> 1192150000
B35: 204 | C35: Réglage et compactage de l'arase de la plateforme des terrassements | D35: m² | E35: =+Attachement!E33 -> 45000 | F35: 2350 | G35: =+E35*F35 -> 105750000 | H35: =+Attachement!F33 -> 0 | I35: =H35*F35 -> 0 | J35: =+Attachement!G33 -> 0 | K35: =+J35*F35 -> 0 | L35: =+J35+H35 -> 0 | M35: =+K35+I35 -> 0 | O35: =+E35-L35 -> 45000 | P35: =+G35-M35 -> 105750000
B36: 205 | C36: Enrochement berge apres purge | D36: m3 | E36: =+Attachement!E34 -> 31000 | F36: 45900 | G36: =+E36*F36 -> 1422900000 | H36: =+Attachement!F34 -> 0 | I36: =H36*F36 -> 0 | J36: =+Attachement!G34 -> 6675 | K36: =+J36*F36 -> 306382500 | L36: =+J36+H36 -> 6675 | M36: =+K36+I36 -> 306382500 | N36: =+M36/G36 -> 0.21532258 | O36: =+E36-L36 -> 24325 | P36: =+G36-M36 -> 1116517500
B37: 206 | C37: Mise en place d'une berge en matériaux traités aux liants hydrauliques | D37: m² | E37: =+Attachement!E35 -> 10200 | F37: 40000 | G37: =+E37*F37 -> 408000000 | H37: =+Attachement!F35 -> 0 | I37: =H37*F37 -> 0 | J37: =+Attachement!G35 -> 0 | K37: =+J37*F37 -> 0 | L37: =+J37+H37 -> 0 | M37: =+K37+I37 -> 0 | N37: =+M37/G37 -> 0 | O37: =+E37-L37 -> 10200 | P37: =+G37-M37 -> 408000000
C38: Total Poste 200 | G38: =+SUBTOTAL(9,G31:G37) -> 3391425000 | I38: =+SUBTOTAL(9,I31:I37) -> 0 | K38: =+SUBTOTAL(9,K31:K37) -> 591454790 | M38: =+SUBTOTAL(9,M31:M37) -> 591454790 | N38: =+M38/G38 -> 0.17439713 | P38: =+SUBTOTAL(9,P31:P37) -> 2799970210
B39: 300 | C39: CHAUSSEE
B40: N° | C40: Désignation | D40: Unités | E40: Quantités
B41: 301 | C41: Fourniture, transport et mise en œuvre de graveleux lateritique pour couche de fondation - épaisseur = 35 cm | D41: m³ | E41: =+Attachement!E39 -> 17000 | F41: 35000 | G41: =+E41*F41 -> 595000000 | H41: =+Attachement!F39 -> 0 | I41: =H41*F41 -> 0 | J41: =+Attachement!G39 -> 0 | K41: =+J41*F41 -> 0 | L41: =+J41+H41 -> 0 | M41: =+K41+I41 -> 0 | N41: =+M41/G41 -> 0 | O41: =+E41-L41 -> 17000 | P41: =+G41-M41 -> 595000000
B42: 302 | C42: Fourniture, transport et mise en œuvre de grave concassé 0/25 pour la couche de base - épaisseur = 25 cm | D42: m³ | E42: =+Attachement!E40 -> 5200 | F42: 72000 | G42: =+E42*F42 -> 374400000 | H42: =+Attachement!F40 -> 0 | I42: =H42*F42 -> 0 | J42: =+Attachement!G40 -> 0 | K42: =+J42*F42 -> 0 | L42: =+J42+H42 -> 0 | M42: =+K42+I42 -> 0 | N42: =+M42/G42 -> 0 | O42: =+E42-L42 -> 5200 | P42: =+G42-M42 -> 374400000
B43: 303 | C43: Fourniture et mise œuvre de beton dosé à 200 Kg/m3 pour revetement de trottoir - épaisseur = 10 cm | D43: m³ | E43: =+Attachement!E41 -> 1020 | F43: 250000 | G43: =+E43*F43 -> 255000000 | H43: =+Attachement!F41 -> 0 | I43: =H43*F43 -> 0 | J43: =+Attachement!G41 -> 0 | K43: =+J43*F43 -> 0 | L43: =+J43+H43 -> 0 | M43: =+K43+I43 -> 0 | N43: =+M43/G43 -> 0 | O43: =+E43-L43 -> 1020 | P43: =+G43-M43 -> 255000000
...
