Workbook

Sheet Page de garde
C3: République Gabonaise
C4: Union - Travail - Justice
A6: Owendo le 30 septembre 2025
A8: RECAPITULATIF TRAVAUX D'AMENAGEMENT DES VOIRIES DE DESSERTE DU QUARTIER AKEMIDJOGONI
A11: VOIES A CONSTRUIRE (6 axes)
A13: Longueur Totale des axes = 1,28126 km (1281,26ml)
A14: RdPoint-LéonMBA=445,46ml / RP-KOMO=115,84ml / Marine-RP=112,60ml / RP-Patrimoine=448,30ml / Amorce BSP=52,00ml / RP-MontagneSte=107,36ml
A16: ASSAINISSEMENT
A18: BASSINS VERSANTS
A19: Longueur = 2136,65 ml
A20: CANIVEAUX
A21: Longueur = 1295 ml
A22: DALOTS
A23: Longueur = 80,4 ml
A26: Devis n° GAO/PRZ/70/30/09/25 du 30/09/2025
A27: N° | B27: Désignation | C27: Unité | D27: Quantité | E27: Prix Unitaire | F27: Montant
A28: 00 - INSTALLATION & ETUDES | H28: =760+1390 -> 2150 | J28: 2136.65 | K28: 3431.65 | L28: 80.4 | M28: 1295
A29: 101-1 | B29: Installation de chantier, amenée et repli du matériel | C29: Fft | D29: 1 | E29: ='Nouveau DQE'!I18 -> 60730000 | F29: =+E29*D29 -> 60730000 | J29: BV | K29: DRAINAGE | L29: Dalots | M29: Can
A30: 101-2 | B30: HESS (Hygiène, Environnement, Santé, Sécurité) | C30: FT | D30: 1 | E30: ='Nouveau DQE'!I19 -> 20410000 | F30: =E30*D30 -> 20410000
A31: 102 | B31: Etudes | C31: Fft | D31: 1 | E31: =SUM('Nouveau DQE'!G21:G26) -> 79920000 | F31: =+E31*D31 -> 79920000
A32: 108 | B32: Déplacement des réseaux (élec + eau + télécoms) | C32: Fft | D32: 1 | E32: =SUM('Nouveau DQE'!G46,'Nouveau DQE'!G73,'Nouveau DQE'!G190) -> 1.6407792e+08 | F32: =+E32*D32 -> 1.6407792e+08
A34: 00- RECAP DES INSTALLATIONS - TRAVAUX PREPARATOIRES - ETUDES & DEPLACEMENT DES RESEAUX | F34: =SUM(F29:F33) -> 3.2513792e+08 | G34: =F34/$K$34/8*7 -> 2.2204368e+08 | H34: =G34/G59 -> 0.083608023 | K34: 1.28126 | L34: Km
A36: 3000 - RECAP DES TRAVAUX DE CONSTRUCTION DES ROUTES (1,28126km ou 1281,26ml) | F36: ='Nouveau DQE'!G316 -> 1.583424e+09 | G36: =F36/$K$34/8*7 -> 1.0813543e+09 | K36: =F36/K34 -> 1.2358335e+09 | L36: km moyen/voirie
A37: Récap des items maintenus, avec anciens prix, mais quantités supérieures | F37: =SUM('Nouveau DQE'!I289,'Nouveau DQE'!I295:I297,) -> 4.1541797e+08 | G37: =F37/$K$34/8*7 -> 2.8369786e+08 | H37: =G37/$G$59 -> 0.10682321
A39: Récap des items maintenus avec anciens prix et quantités inférieures | F39: =SUM('Nouveau DQE'!I309,'Nouveau DQE'!I303:I307,'Nouveau DQE'!I290) -> 1.0425221e+09 | G39: =F39/$K$34/8*7 -> 7.1196076e+08 | H39: =G39/$G$59 -> 0.26808073
A41: Récap des nouveaux prix | F41: =SUM('Nouveau DQE'!I291,'Nouveau DQE'!I298) -> 1.2548395e+08 | G41: =F41/$K$34/8*7 -> 85695685 | H41: =G41/$G$59 -> 0.032267736 | K41: =F41+F39+F37 -> 1.583424e+09
A43: 500 - Recap des BASSINS VERSANTS & ASSAINISSEMENTS DIVERS | F43: =+F44+F46+F48 -> 1590529039 | G43: =F43/$K$34/8*7 -> 1.0862065e+09
A44: Récap des items maintenus, avec anciens prix, mais quantités supérieures | F44: =+'Nouveau DQE'!J440 -> 106427650 | G44: =F44/$K$34/8*7 -> 72681730 | H44: =G44/$G$59 -> 0.027367479
A46: Récap des items maintenus avec anciens prix et quantités inférieures | F46: =+'Nouveau DQE'!J425 -> 2816640 | G46: =F46/$K$34/8*7 -> 1923544 | H46: =G46/$G$59 -> 0.00072428863
A48: Récap des nouveaux prix | F48: =+'Nouveau DQE'!J346 -> 1481284749 | G48: =F48/$K$34/8*7 -> 1.0116012e+09 | H48: =G48/$G$59 -> 0.38090693
A50: RECAP BUDGET DES INDEMNISATIONS HORS CHIFFRAGE MIKA SERVICES ET AMENAGEMENTS SPECIFIQUES | F50: =SUM(F51:F57) -> 3.8974541e+08 | G50: =F50/$K$34/8*7 -> 2.6616552e+08 | L50: =G50/$G$59 -> 0.1002216
A51: A - Enveloppe des expropriations, droits de passages sur terrains, démolition&reconstructions des barrières | F51: =+'Nouveau DQE'!G562 -> 50874162 | G51: =F51/$K$34/8*7 -> 34743059 | H51: =G51/$G$59 -> 0.013082104
A53: B - Amenagement divers plateaux sportifs / parking | F53: =+'Nouveau DQE'!G573 -> 230000000 | G53: =F53/$K$34/8*7 -> 1.5707194e+08 | H53: =G53/$G$59 -> 0.059143655
A55: C - Autres aménagements | F55: =+'Nouveau DQE'!G575 -> 83871250 | G55: =F55/$K$34/8*7 -> 57277480 | H55: =G55/$G$59 -> 0.021567184
A57: D - Aménagements et/ou dévoiements de réseaux non prévus | F57: =+'Nouveau DQE'!G620 -> 25000000 | G57: =F57/$K$34/8*7 -> 17073037 | H57: =G57/$G$59 -> 0.0064286582
A59: TOTAL HTVA | F59: =ROUNDUP(+F50+F43+F36+F34,0) -> 3888836403 | G59: =F59/$K$34/8*7 -> 2.65577e+09 | H59: =+SUM(H57,H55,H53,H51,H48,H46,H44,H41,H39,H37,H36,H34) -> 1 | L59: Moyenne 1,2Mds/km
A60: CCS (1%) | F60: =+F59*0.01 -> 38888364
A61: TVA (18%) | F61: =+F59*0.18 -> 6.9999055e+08
A62: TOTAL GENERAL TTC | F62: =SUM(F59:F61) -> 4.6277153e+09
A63: Code couleur
...

Sheet Nouveau DQE
E2: République Gabonaise
E3: Union - Travail - Justice | I3: ancien + qté sup
I4: ancien + qté inf | N4: coef. Vente | O4: FFx | P4: Terr. | Q4: BAC+ Ass.
I5: nouveau prix | O5: 1.15 | P5: 1.3 | Q5: 1.4
A6: DEVIS QUANTITATIF ESTIMATIF
A7: TRAVAUX D'AMENAGEMENT DES VOIRIES DE DESSERTE DU QUARTIER AKEMIDJOGONI | K7: Excédent - HT
A9: Structure de chaussée : Enrochement de blocs létéritiques 400/600/800 + Graveleux Latétéritique GL0/25=0,25m en consolidation pour couche de forme + Fondation en grave non traitée GNT 0/25 = 0,20m + Béton Armé Continu (BAC) épaisseur 0,15m en base-roulement + 2*1,5ml de trottoir + bassin versant&allée contigue + parking+ terrain de sport | K9: =O557 -> -0.2938314
A10: Linéaire chaussée en béton armé continu BAC = 1281,26ml _//_ Linéaire cumulé d'ouvrages d'assainissements (Bassins versants/canal/exutoires/ouvrages hydrauliques/dalots) = 3512,05ml | K10: =E283 -> 1281.26 | L10: =SUM(E346,E362,E363,E378,E393,E394,E410,E425,E440,E442,E443,E444,E459,E474,E476,E477,E496,E497,E515,E534,E553) -> 3512.05
A12: PROJET AKEMIDJOGONI
A14: Devis n° GAO/PRZ/70/30/09/25 du 30/09/2025
A15: N° Prix | B15: Désignation | C15: Unités | D15: Nb | E15: Quantités | F15: Prix unitaire | G15: Prix total | K15: brut | L15: Peines & soins | M15: cdc | N15: DS/revient | O15: VENTE | P15: marge
A16: Chapitre 100 - Travaux Préparatoires | L16: 0.1 | M16: 0.02
A17: 101 | B17: Frais fixes | C17: FT | D17: 1 | E17: 1
A18: 101-1 | B18: Installation de chantier - A/R personnel et matériel | C18: FT | D18: 1 | E18: 1 | F18: =60730000 -> 60730000 | G18: =F18*E18 -> 60730000 | I18: =G18 -> 60730000 | K18: 35000000 | L18: =K18*$L$16 -> 3500000 | M18: =K18*$M$16 -> 700000 | N18: =SUM(K18:M18) -> 39200000 | O18: =N18*$O$5 -> 45080000 | P18: =O18-N18 -> 5880000
A19: 101-2 | B19: Enveloppe QHSE | C19: FT | D19: 1 | E19: 1 | F19: =20410000 -> 20410000 | G19: =F19*E19 -> 20410000 | I19: =G19 -> 20410000 | K19: 4000000 | L19: =K19*$L$16 -> 400000 | M19: =K19*$M$16 -> 80000 | N19: =SUM(K19:M19) -> 4480000 | O19: =N19*$O$5 -> 5152000 | P19: =O19-N19 -> 672000
A20: =A17+1 -> 102 | B20: Etudes | C20: FT | D20: 1 | E20: 1
A21: 102;1 | B21: Process documentaire | C21: FT | D21: 1 | E21: 1 | F21: =10400000 -> 10400000 | G21: =F21*E21 -> 10400000 | I21: =SUM(G21:G26) -> 79920000
A22: 102;2 | B22: Etudes topo | C22: FT | D22: 1 | E22: 1 | F22: 18280000 | G22: =F22*E22 -> 18280000
A23: 102;3 | B23: Etudes géotechniques | C23: FT | D23: 1 | E23: 1 | F23: 29860000 | G23: =F23*E23 -> 29860000
A24: 102;4 | B24: Elaboration Dossier constructeur/EXE + DFA | C24: FT | D24: 1 | E24: 1 | F24: =3600000 -> 3600000 | G24: =F24*E24 -> 3600000
A25: 102;5 | B25: Hydraulique - Hydraologie - Assainissement | C25: FT | D25: 1 | E25: 1 | F25: =MROUND(O25,20000) -> 10040000 | G25: =F25*E25 -> 10040000 | K25: 8300000 | L25: =K25*$L$16 -> 830000 | M25: =K25*$M$16 -> 166000 | N25: =SUM(K25:M25) -> 9296000 | O25: =N25*$Q$25 -> 10039680 | P25: =O25-N25 -> 743680 | Q25: 1.08
A26: 102;6 | B26: NIES | C26: FT | D26: 1 | E26: 1 | F26: =MROUND(O26,20000) -> 7740000 | G26: =F26*E26 -> 7740000 | K26: 6400000 | L26: =K26*$L$16 -> 640000 | M26: =K26*$M$16 -> 128000 | N26: =SUM(K26:M26) -> 7168000 | O26: =N26*$Q$25 -> 7741440 | P26: =O26-N26 -> 573440
A27: =A20+1 -> 103 | B27: Néttoyage et décapage du site | C27: m² | D27: 1 | E27: =E28 -> 23983 | F27: =MROUND(O27,5) -> 1110 | G27: Pour mémoire | K27: =SUM(G28:G37)/$E27 -> 861.54734 | L27: =K27*$L$16 -> 86.154734 | M27: =K27*$M$16 -> 17.230947 | N27: =SUM(K27:M27) -> 964.93302 | O27: =N27*$O$5 -> 1109.673 | P27: =O27-N27 -> 144.73995
B28: Surface cible = 23,983m² | C28: fft | D28: 1 | E28: =23983 -> 23983
B29: volume = 23,893 * 0,2 | C29: m² | D29: 1 | E29: =E28*0.2 -> 4796.6
B30: Pelle (40 camions/jr) | C30: u | D30: =MROUND(E29/(12*40),0.05) -> 10 | E30: 1 | F30: =7500000/26 -> 288461.54 | G30: =F30*E30*D30 -> 2884615.4
B31: bull | C31: u | D31: =D30 -> 10 | E31: =E30 -> 1 | F31: =7500000/26 -> 288461.54 | G31: =F31*E31*D31 -> 2884615.4
B32: niveleuse | C32: u | D32: =D31 -> 10 | E32: 1 | F32: =8000000/26 -> 307692.31 | G32: =F32*E32*D32 -> 3076923.1
B33: Gasoil engins | C33: lt | D33: =D31 -> 10 | E33: =SUM(E30:E32)*100 -> 300 | F33: =1045 -> 1045 | G33: =F33*E33*D33 -> 3135000
B34: camion benne + chauffeur + GO | C34: u | D34: =D32 -> 10 | E34: 4 | F34: =200000/1.095 -> 182648.4 | G34: =F34*E34*D34 -> 7305936.1
B35: Conducteur engins | C35: Unités | D35: =D30 -> 10 | E35: =SUM(E30:E32) -> 3 | F35: =MROUND((350000/176.33)*1.225*12,10) -> 29180 | G35: =F35*E35*D35 -> 875400
B36: HTM | C36: Unités | D36: =D30 -> 10 | E36: =1+E35 -> 4 | F36: =MROUND((150000/176.33)*1.225*12,10) -> 12500 | G36: =F36*E36*D36 -> 500000
A38: =A27+1 -> 104 | B38: Compteur eau à déplacer | C38: Unités | D38: 1 | E38: 44 | F38: 210000 | G38: Pour mémoire | Q38: ATTENTE MOUSSA !!!!!
A39: =A38+1 -> 105 | B39: Poste de Transformateur électrique à déplacer | C39: Unités | D39: 1 | E39: 1 | F39: 17710000 | G39: Pour mémoire
A40: =A39+1 -> 106 | B40: Poteau électrique Basse Tensions (BT) à déplacer | C40: Unités | D40: 1 | E40: 7 | F40: 5390000 | G40: Pour mémoire
A41: =A40+1 -> 107 | B41: Poteau électrique Haute Tensions (HT) à déplacer | C41: Unités | D41: 1 | E41: 3 | F41: 7080000 | G41: Pour mémoire
A42: 108 | B42: Déplacement des réseaux
A43: 108.1 | B43: Travaux préparatoires
A44: 101 | B44: Installation de chantier / Mobilisation et démobilisation d'équipe / Repli | C44: ens | D44: 1 | E44: 1 | F44: =MROUND(K44/$M$49,10) -> 3146070 | G44: =F44*E44*D44 -> 3146070 | J44: 3733330 | K44: =500000+500000+500000+500000+200000+200000+200000+200000 -> 2800000 | L44: =L42*K44 -> 0 | M44: =K44/M42 -> #DIV/0! | N44: =1-K44/L44 -> #DIV/0! | O44: =1-K44/M44 -> #DIV/0! | P44: =F44/K44 -> 1.1235964
A45: 102 | B45: Panneaux de signalisation / Balisage | C45: ens | D45: 1 | E45: 1 | F45: =MROUND(K45/$M$49,10) -> 2786520 | G45: =F45*E45*D45 -> 2786520 | J45: 3348000 | K45: =240000+240000+300000+200000+300000+200000+300000+200000+300000+200000 -> 2480000
...

Sheet etude pxi DV
A2: ETUDE DE PRIX Ouvrages Hydrauliques AKEMIDJOGONI
I4: brut | J4: Peines & soins | K4: cdc | L4: DS/revient | M4: VENTE/ml | N4: marge
J5: 0.1 | K5: 0.02 | M5: 1.35
I7: =SUM(G12:G58)/$E11 -> 1193956.5 | J7: =I7*$J$5 -> 119395.65 | K7: =I7*$K$5 -> 23879.13 | L7: =SUM(I7:K7) -> 1337231.3 | M7: =L7*$M$5 -> 1805262.2 | N7: =M7-L7 -> 468030.94
A9: DELTA VISION | I9: MIKA
A10: Code | B10: Désignation | C10: Unité | D10: nb | E10: Quantité | F10: Prix unitaire | G10: Prix de vente | I10: PU MIKA | J10: PT MIKA
A11: 1 | B11: Dalot OH 3 section 2*(2*1,8) / 2 chambres | C11: ml | E11: 12 | F11: 420000 | G11: 5040000 | I11: =+MROUND(M7,10) -> 1805260 | J11: =+I11*E11 -> 21663120
B12: terrassements
B13: fouilles | C13: m3 | D13: 1 | E13: =(9*17+13*5.6)/2*3.5 -> 395.15
B14: Pelle 400m3/jr fouilles | C14: u | D14: =E13/400 -> 0.987875 | E14: 1 | F14: =7500000/26 -> 288461.54 | G14: =F14*E14*D14 -> 284963.94
B15: gasoil | C15: u | D15: =100*D14 -> 98.7875 | E15: 1 | F15: 1050 | G15: =F15*E15*D15 -> 103726.88
B16: enrochement | C16: m3 | D16: 1 | E16: =17*9*1 -> 153
B17: Pelle 400m3/jr enrochement | C17: u | D17: =E16/400 -> 0.3825 | E17: 1 | F17: =7500000/26 -> 288461.54 | G17: =F17*E17*D17 -> 110336.54
B18: gasoil | C18: u | D18: =100*D17 -> 38.25 | E18: 1 | F18: 1050 | G18: =F18*E18*D18 -> 40162.5
B19: Pelle | C19: u | E19: 1 | F19: =7500000/26 -> 288461.54 | G19: =F19*E19*D19 -> 0
B20: terrassements | G20: =F20*E20*D20 -> 0
B21: terrassements | G21: =F21*E21*D21 -> 0
B22: terrassements | G22: =F22*E22*D22 -> 0
B23: MEO de gnt 0,25 13*5,6*0,10m | C23: Tonne | D23: =1.85 -> 1.85 | E23: =(13*5.6*0.1) -> 7.28 | F23: 22000 | G23: =F23*E23*D23 -> 296296
B25: béton de propreté 13*5,6*0,10m | C25: m3 | D25: 1 | E25: =13*5.6*0.1 -> 7.28 | F25: 100000 | G25: =F25*E25*D25 -> 728000
B26: geotextile | C26: rlx | D26: 1 | E26: =MROUND(SUM(E27:E28)/1080,0.0005) -> 0.188 | F26: =1050000 -> 1050000 | G26: =F26*E26*D26 -> 197400
B27: geotextile sur gnt | C27: m² | D27: 1 | E27: =13*5.6 -> 72.8
B28: geotextile sur pipe | C28: m² | D28: 1 | E28: =(2.2*2+0.5*2+4.6)*13 -> 130
B29: Flintkote | C29: kg | D29: 1 | E29: =MROUND(SUM(E27:E28)*0.4,0.0005) -> 81.12
B30: nbre de pot/ conditionnement de 25kg | C30: u | D30: 1 | E30: =ROUNDUP(E29/25,0) -> 4 | F30: 45000 | G30: =F30*E30*D30 -> 180000
B31: radier
B32: béton 4,60*12*0,2 | C32: m3 | D32: 1 | E32: =4.6*12*0.2 -> 11.04 | F32: 120000 | G32: =F32*E32*D32 -> 1324800 | I32: Type | J32: Montant/tot | K32: rep/m3/béton | L32: qté coffrage | M32: béton
B33: aciers | C33: kg | D33: 1 | E33: =82*E32 -> 905.28 | F33: =700 -> 700 | G33: =F33*E33*D33 -> 633696 | I33: Coffrage radier | J33: =SUM(G35:G37) -> 62660 | K33: =J33/E32 -> 5675.7246 | L33: =E34 -> 6.64 | M33: =E32+E39+E45 -> 35.04
B34: coffrage | C34: m² | D34: 1 | E34: =(12+4.6)*2*0.2 -> 6.64 | I34: Coffrage voiles | J34: =SUM(G42:G43) -> 362940 | K34: =J34/E39 -> 28004.63 | L34: =E41 -> 131.76
B35: cp 19mm (3,05m²) | C35: u | D35: =1/3 -> 0.33333333 | E35: =ROUNDUP(E34/3.05,0) -> 3 | F35: 22500 | G35: =F35*E35*D35 -> 22500 | I35: Coffrage tablier | J35: =SUM(G48:G50) -> 909960 | K35: =J35/E47 -> 8284.4137 | L35: =E47 -> 109.84
B36: pointes | C36: kg | D36: 1 | E36: =0.2*E34 -> 1.328 | F36: =1250 -> 1250 | G36: =F36*E36*D36 -> 1660 | J36: =SUM(J33:J35) -> 1335560 | K36: =AVERAGE(K33:K35) -> 13988.256 | L36: =SUM(L33:L35) -> 248.24
B37: chevrons | C37: u | D37: 1 | E37: =ROUNDUP(E34/1,0) -> 7 | F37: =5500 -> 5500 | G37: =F37*E37*D37 -> 38500 | I37: =E33/E32 -> 82
B38: voiles/3
B39: béton 1,8*3*0,3 * 12 | C39: m3 | D39: 1 | E39: =(1.8*0.2*E11)*3 -> 12.96 | F39: 120000 | G39: =F39*E39*D39 -> 1555200
B40: aciers | C40: kg | D40: 1 | E40: =E39*82 -> 1062.72 | F40: 700 | G40: =F40*E40*D40 -> 743904 | I40: =E40/E39 -> 82
B41: coffrage | C41: m² | D41: 1 | E41: =(1.8*12*2+1.8*0.2*2)*3 -> 131.76
B42: cp 19mm (3,05m²) | C42: m² | D42: =1/3 -> 0.33333333 | E42: =ROUNDUP(E41/3.05,0) -> 44 | F42: 22500 | G42: =F42*E42*D42 -> 330000
B43: pointes | C43: kg | D43: 1 | E43: =E41*0.2 -> 26.352 | F43: 1250 | G43: =F43*E43*D43 -> 32940
B44: Tablier | G44: =F44*E44*D44 -> 0
B45: béton 4,60*12*0,2 | C45: m3 | D45: 1 | E45: =4.6*12*0.2 -> 11.04 | F45: 120000 | G45: =F45*E45*D45 -> 1324800
...

Sheet DQ ouvrages
A1: DEVIS QUANTITATIF
A2: TRAVAUX DE CONSTRUCTION D'OUVRAGES DE DRAINAGE DE LA ROUTE AKIMIDJONGONI
A5: N° PRIX | B5: DESIGNATION | C5: QUANTITE | D5: UNITE
A6: Sous total 100
A7: SECTION 100 | B7: OUVRAGES DE DRAINAGE
A8: 100.1 | B8: CANAL PRINCIPAL
B9: Travaux de réalisation d'un canal rectangulaiire de section b=1.5m h 1.5m L 130m (Vers marrine-Rond point)
A10: 100.1.1 | B10: Beton de proprété C 150 | C10: 19.5 | D10: m3 | E10: ok
A11: 100.1.2 | B11: Coffrages | C11: 585 | D11: m2
A12: 100.1.3 | B12: Aciers à haute adhérence | C12: 11466 | D12: kg
A13: 100.1.4 | B13: Béton de qualité Q 350 au ciment CPA 350 | C13: 127.4 | D13: m3
A14: 100.1.5 | B14: Réalisation des barbacanes | C14: 780 | D14: unité
A15: 100.1.7 | B15: Fouille | C15: 994.5 | D15: m2
B16: Travaux de réalisation d'un canal rectangulaire de section b=3m h 1.5m L 40m (suite-Axe Montagne sainte)
A17: 100.1.1 | B17: Beton de proprété C 150 | C17: 12 | D17: m3 | E17: ok
A18: 100.1.2 | B18: Coffrages | C18: 240 | D18: m2
A19: 100.1.3 | B19: Aciers à haute adhérence | C19: 4608 | D19: kg
A20: 100.1.4 | B20: Béton de qualité Q 350 au ciment CPA 350 | C20: 51.2 | D20: m3
A21: 100.1.5 | B21: Réalisation des barbacanes | C21: 240 | D21: unité
A22: 100.1.7 | B22: Fouille | C22: 396 | D22: m2
B23: Travaux de réalisation d'un canal rectangulaire de section b=4m h 1.8m L 360m (Montagne sainte-Patrimoine)
A24: 100.1.1 | B24: Beton de proprété C 150 | C24: 144 | D24: m3 | E24: ok
A25: 100.1.2 | B25: Coffrages | C25: 2736 | D25: m2
A26: 100.1.3 | B26: Aciers à haute adhérence | C26: 51840 | D26: kg
A27: 100.1.4 | B27: Béton de qualité Q 350 au ciment CPA 350 | C27: 576 | D27: m3
A28: 100.1.5 | B28: Réalisation des barbacanes | C28: 2160 | D28: unité
A29: 100.1.7 | B29: Fouille | C29: 5313.6 | D29: m2
A30: 1.4 | B30: Travaux de réalisation d'un canal rectangulaire de section b=4.5m h 1.8m L 165m (Patrimoine - racollement canal existant exutoire)
A31: 100.1.1 | B31: Beton de proprété C 150 | C31: 162 | D31: m3
A32: 100.1.2 | B32: Coffrages | C32: 2928.4403 | D32: m2
A33: 100.1.3 | B33: Aciers à haute adhérence | C33: 55303.925 | D33: kg
A34: 100.1.4 | B34: Béton de qualité Q 350 au ciment CPA 350 | C34: 614.48806 | D34: m3
A35: 100.1.5 | B35: Réalisation des barbacanes | C35: 2160 | D35: unité
A36: 100.1.7 | B36: Fouille | C36: 5659.9925 | D36: m2
A37: 100.2 | B37: RACORDEMENT AU CANAL PRINCIPAL(descente Montagne Sainte Axe 2) voie carrefour Léon M'BA-Rond poin (Axe 1)
A38: 2.1 | B38: Travaux de réalisation d'un canal rectangulaire de section h 1.5m et b= 2m L 35m | E38: OK
A39: 100.2.1 | B39: Beton de proprété C 150 | C39: 7 | D39: m3
A40: 100.2.2 | B40: Coffrages | C40: 175 | D40: m2
A41: 100.2.3 | B41: Aciers à haute adhérence | C41: 3402 | D41: kg
A42: 100.2.4 | B42: Béton de qualité Q 350 au ciment CPA 350 | C42: 37.8 | D42: m3
...
